Workbook

Sheet Grade
A1: Final Exam Result
D3: Module: Introduction to Data Science and AI | H3: Exam Date: 25.06.2024
D4: Lecturer: Dr. Nguyen Tuan Cuong | H4: Time: 09:30 - 11:00
D5: Semester: SS2024 | H5: Duration: 90 minutes
A8: No. | B8: Intake | C8: VGU ID | D8: Last Names and Middle Names | E8: Names | F8: Attempts | G8: Emails | H8: Grade | I8: Note | J8: Lab 1 | K8: Lab 2 | L8: Final (40%) | M8: Project (40%) | N8: Bonus | R8: Grade | S8: German
A9: 1 | B9: CSE2021 | C9: 10421133 | D9: Bui Le | E9: Nhat | F9: 1 | G9: 10421133@student.vgu.edu.vn | H9: 5 | J9: =VLOOKUP(C9,Lab!$C$9:$I$126, 6, FALSE) -> 10 | K9: =VLOOKUP(C9,Lab!$C$9:$I$126, 7, FALSE) -> 10 | L9: =_xlfn.IFNA(VLOOKUP(C9, exam!$A$2:$C$115,3,FALSE),0) -> 0.25 | O9: No submission | R9: =J9*0.1+K9*0.1+MIN((L9+N9),10)*0.4+M9*0.4 -> 2.1 | S9: =IF(R9*10<50,5,ROUND(3*((100-R9*10)/50)+1,1)) -> 5 | T9: =IF(S9>4,5,IF((S9-TRUNC(S9))<0.3,TRUNC(S9),IF((S9-TRUNC(S9))>=0.7,TRUNC(S9)+0.7,TRUNC(S9)+0.3))) -> 5
A10: 2 | B10: CSE2021 | C10: 10421127 | D10: Bui Van Hoang | E10: Vu | F10: 1 | G10: 10421127@student.vgu.edu.vn | H10: 1.3 | J10: =VLOOKUP(C10,Lab!$C$9:$I$126, 6, FALSE) -> 10 | K10: =VLOOKUP(C10,Lab!$C$9:$I$126, 7, FALSE) -> 10 | L10: =_xlfn.IFNA(VLOOKUP(C10, exam!$A$2:$C$115,3,FALSE),0) -> 7 | M10: 10 | N10: 1 | R10: =J10*0.1+K10*0.1+MIN((L10+N10),10)*0.4+M10*0.4 -> 9.2 | S10: =IF(R10*10<50,5,ROUND(3*((100-R10*10)/50)+1,1)) -> 1.5 | T10: =IF(S10>4,5,IF((S10-TRUNC(S10))<0.3,TRUNC(S10),IF((S10-TRUNC(S10))>=0.7,TRUNC(S10)+0.7,TRUNC(S10)+0.3))) -> 1.3
A11: 3 | B11: CSE2022 | C11: 10422002 | D11: Pham Duc | E11: An | F11: 1 | G11: 10422002@student.vgu.edu.vn | H11: 2.3 | J11: =VLOOKUP(C11,Lab!$C$9:$I$126, 6, FALSE) -> 0 | K11: =VLOOKUP(C11,Lab!$C$9:$I$126, 7, FALSE) -> 10 | L11: =_xlfn.IFNA(VLOOKUP(C11, exam!$A$2:$C$115,3,FALSE),0) -> 7.25 | M11: 10 | N11: 0 | R11: =J11*0.1+K11*0.1+MIN((L11+N11),10)*0.4+M11*0.4 -> 7.9 | S11: =IF(R11*10<50,5,ROUND(3*((100-R11*10)/50)+1,1)) -> 2.3 | T11: =IF(S11>4,5,IF((S11-TRUNC(S11))<0.3,TRUNC(S11),IF((S11-TRUNC(S11))>=0.7,TRUNC(S11)+0.7,TRUNC(S11)+0.3))) -> 2.3
A12: 4 | B12: CSE2022 | C12: 10422003 | D12: Le Thai | E12: An | F12: 1 | G12: 10422003@student.vgu.edu.vn | H12: 4 | J12: =VLOOKUP(C12,Lab!$C$9:$I$126, 6, FALSE) -> 10 | K12: =VLOOKUP(C12,Lab!$C$9:$I$126, 7, FALSE) -> 10 | L12: =_xlfn.IFNA(VLOOKUP(C12, exam!$A$2:$C$115,3,FALSE),0) -> 5.5 | M12: 2 | R12: =J12*0.1+K12*0.1+MIN((L12+N12),10)*0.4+M12*0.4 -> 5 | S12: =IF(R12*10<50,5,ROUND(3*((100-R12*10)/50)+1,1)) -> 4 | T12: =IF(S12>4,5,IF((S12-TRUNC(S12))<0.3,TRUNC(S12),IF((S12-TRUNC(S12))>=0.7,TRUNC(S12)+0.7,TRUNC(S12)+0.3))) -> 4
A13: 5 | B13: CSE2022 | C13: 10422004 | D13: Yamashita Tri | E13: An | F13: 1 | G13: 10422004@student.vgu.edu.vn | H13: 1 | J13: =VLOOKUP(C13,Lab!$C$9:$I$126, 6, FALSE) -> 10 | K13: =VLOOKUP(C13,Lab!$C$9:$I$126, 7, FALSE) -> 10 | L13: =_xlfn.IFNA(VLOOKUP(C13, exam!$A$2:$C$115,3,FALSE),0) -> 9 | M13: 10 | N13: 1 | R13: =J13*0.1+K13*0.1+MIN((L13+N13),10)*0.4+M13*0.4 -> 10 | S13: =IF(R13*10<50,5,ROUND(3*((100-R13*10)/50)+1,1)) -> 1 | T13: =IF(S13>4,5,IF((S13-TRUNC(S13))<0.3,TRUNC(S13),IF((S13-TRUNC(S13))>=0.7,TRUNC(S13)+0.7,TRUNC(S13)+0.3))) -> 1
A14: 6 | B14: CSE2022 | C14: 10222040 | D14: Vu Duc Hung | E14: Anh | F14: 1 | G14: 10222040@student.vgu.edu.vn | H14: 5 | J14: =VLOOKUP(C14,Lab!$C$9:$I$126, 6, FALSE) -> 0 | K14: =VLOOKUP(C14,Lab!$C$9:$I$126, 7, FALSE) -> 10 | L14: =_xlfn.IFNA(VLOOKUP(C14, exam!$A$2:$C$115,3,FALSE),0) -> 4.25 | O14: Private code, not able to access | R14: =J14*0.1+K14*0.1+MIN((L14+N14),10)*0.4+M14*0.4 -> 2.7 | S14: =IF(R14*10<50,5,ROUND(3*((100-R14*10)/50)+1,1)) -> 5 | T14: =IF(S14>4,5,IF((S14-TRUNC(S14))<0.3,TRUNC(S14),IF((S14-TRUNC(S14))>=0.7,TRUNC(S14)+0.7,TRUNC(S14)+0.3))) -> 5
A15: 7 | B15: CSE2022 | C15: 10422005 | D15: Nguyen Tran Tuan | E15: Anh | F15: 1 | G15: 10422005@student.vgu.edu.vn | H15: 1.7 | J15: =VLOOKUP(C15,Lab!$C$9:$I$126, 6, FALSE) -> 0 | K15: =VLOOKUP(C15,Lab!$C$9:$I$126, 7, FALSE) -> 10 | L15: =_xlfn.IFNA(VLOOKUP(C15, exam!$A$2:$C$115,3,FALSE),0) -> 8 | M15: 10 | N15: 1 | R15: =J15*0.1+K15*0.1+MIN((L15+N15),10)*0.4+M15*0.4 -> 8.6 | S15: =IF(R15*10<50,5,ROUND(3*((100-R15*10)/50)+1,1)) -> 1.8 | T15: =IF(S15>4,5,IF((S15-TRUNC(S15))<0.3,TRUNC(S15),IF((S15-TRUNC(S15))>=0.7,TRUNC(S15)+0.7,TRUNC(S15)+0.3))) -> 1.7
A16: 8 | B16: CSE2022 | C16: 10422006 | D16: Nguyen Nhat | E16: Anh | F16: 1 | G16: 10422006@student.vgu.edu.vn | H16: 2 | J16: =VLOOKUP(C16,Lab!$C$9:$I$126, 6, FALSE) -> 10 | K16: =VLOOKUP(C16,Lab!$C$9:$I$126, 7, FALSE) -> 10 | L16: =_xlfn.IFNA(VLOOKUP(C16, exam!$A$2:$C$115,3,FALSE),0) -> 4.75 | M16: 10 | N16: 1 | R16: =J16*0.1+K16*0.1+MIN((L16+N16),10)*0.4+M16*0.4 -> 8.3 | S16: =IF(R16*10<50,5,ROUND(3*((100-R16*10)/50)+1,1)) -> 2 | T16: =IF(S16>4,5,IF((S16-TRUNC(S16))<0.3,TRUNC(S16),IF((S16-TRUNC(S16))>=0.7,TRUNC(S16)+0.7,TRUNC(S16)+0.3))) -> 2
A17: 9 | B17: CSE2022 | C17: 10422009 | D17: Nguyen Ngoc Minh | E17: Anh | F17: 1 | G17: 10422009@student.vgu.edu.vn | H17: 2 | J17: =VLOOKUP(C17,Lab!$C$9:$I$126, 6, FALSE) -> 8 | K17: =VLOOKUP(C17,Lab!$C$9:$I$126, 7, FALSE) -> 10 | L17: =_xlfn.IFNA(VLOOKUP(C17, exam!$A$2:$C$115,3,FALSE),0) -> 5.5 | M17: 10 | N17: 1 | R17: =J17*0.1+K17*0.1+MIN((L17+N17),10)*0.4+M17*0.4 -> 8.4 | S17: =IF(R17*10<50,5,ROUND(3*((100-R17*10)/50)+1,1)) -> 2 | T17: =IF(S17>4,5,IF((S17-TRUNC(S17))<0.3,TRUNC(S17),IF((S17-TRUNC(S17))>=0.7,TRUNC(S17)+0.7,TRUNC(S17)+0.3))) -> 2
A18: 10 | B18: CSE2022 | C18: 10422086 | D18: Dang Dinh Tu | E18: Anh | F18: 1 | G18: 10422086@student.vgu.edu.vn | H18: 1.3 | J18: =VLOOKUP(C18,Lab!$C$9:$I$126, 6, FALSE) -> 10 | K18: =VLOOKUP(C18,Lab!$C$9:$I$126, 7, FALSE) -> 10 | L18: =_xlfn.IFNA(VLOOKUP(C18, exam!$A$2:$C$115,3,FALSE),0) -> 7.75 | M18: 10 | N18: 1 | O18: bonus 2 not active | R18: =J18*0.1+K18*0.1+MIN((L18+N18),10)*0.4+M18*0.4 -> 9.5 | S18: =IF(R18*10<50,5,ROUND(3*((100-R18*10)/50)+1,1)) -> 1.3 | T18: =IF(S18>4,5,IF((S18-TRUNC(S18))<0.3,TRUNC(S18),IF((S18-TRUNC(S18))>=0.7,TRUNC(S18)+0.7,TRUNC(S18)+0.3))) -> 1.3
A19: 11 | B19: CSE2022 | C19: 10422087 | D19: Ho Viet | E19: Bach | F19: 1 | G19: 10422087@student.vgu.edu.vn | H19: 1.3 | J19: =VLOOKUP(C19,Lab!$C$9:$I$126, 6, FALSE) -> 10 | K19: =VLOOKUP(C19,Lab!$C$9:$I$126, 7, FALSE) -> 10 | L19: =_xlfn.IFNA(VLOOKUP(C19, exam!$A$2:$C$115,3,FALSE),0) -> 6.75 | M19: 10 | N19: 1 | R19: =J19*0.1+K19*0.1+MIN((L19+N19),10)*0.4+M19*0.4 -> 9.1 | S19: =IF(R19*10<50,5,ROUND(3*((100-R19*10)/50)+1,1)) -> 1.5 | T19: =IF(S19>4,5,IF((S19-TRUNC(S19))<0.3,TRUNC(S19),IF((S19-TRUNC(S19))>=0.7,TRUNC(S19)+0.7,TRUNC(S19)+0.3))) -> 1.3
A20: 12 | B20: CSE2022 | C20: 10421069 | D20: Tran Gia | E20: Bao | F20: 1 | G20: 10421069@student.vgu.edu.vn | H20: 5 | J20: =VLOOKUP(C20,Lab!$C$9:$I$126, 6, FALSE) -> 0 | K20: =VLOOKUP(C20,Lab!$C$9:$I$126, 7, FALSE) -> 10 | L20: =_xlfn.IFNA(VLOOKUP(C20, exam!$A$2:$C$115,3,FALSE),0) -> 6.5 | R20: =J20*0.1+K20*0.1+MIN((L20+N20),10)*0.4+M20*0.4 -> 3.6 | S20: =IF(R20*10<50,5,ROUND(3*((100-R20*10)/50)+1,1)) -> 5 | T20: =IF(S20>4,5,IF((S20-TRUNC(S20))<0.3,TRUNC(S20),IF((S20-TRUNC(S20))>=0.7,TRUNC(S20)+0.7,TRUNC(S20)+0.3))) -> 5
A21: 13 | B21: CSE2022 | C21: 10421125 | D21: Phan Le Quoc | E21: Bao | F21: 1 | G21: 10421125@student.vgu.edu.vn | H21: 5 | J21: =VLOOKUP(C21,Lab!$C$9:$I$126, 6, FALSE) -> 0 | K21: =VLOOKUP(C21,Lab!$C$9:$I$126, 7, FALSE) -> 10 | L21: =_xlfn.IFNA(VLOOKUP(C21, exam!$A$2:$C$115,3,FALSE),0) -> 6.25 | R21: =J21*0.1+K21*0.1+MIN((L21+N21),10)*0.4+M21*0.4 -> 3.5 | S21: =IF(R21*10<50,5,ROUND(3*((100-R21*10)/50)+1,1)) -> 5 | T21: =IF(S21>4,5,IF((S21-TRUNC(S21))<0.3,TRUNC(S21),IF((S21-TRUNC(S21))>=0.7,TRUNC(S21)+0.7,TRUNC(S21)+0.3))) -> 5
A22: 14 | B22: CSE2022 | C22: 10422011 | D22: Huynh Thien | E22: Bao | F22: 1 | G22: 10422011@student.vgu.edu.vn | H22: 1.3 | J22: =VLOOKUP(C22,Lab!$C$9:$I$126, 6, FALSE) -> 10 | K22: =VLOOKUP(C22,Lab!$C$9:$I$126, 7, FALSE) -> 10 | L22: =_xlfn.IFNA(VLOOKUP(C22, exam!$A$2:$C$115,3,FALSE),0) -> 6.5 | M22: 10 | N22: 2 | R22: =J22*0.1+K22*0.1+MIN((L22+N22),10)*0.4+M22*0.4 -> 9.4 | S22: =IF(R22*10<50,5,ROUND(3*((100-R22*10)/50)+1,1)) -> 1.4 | T22: =IF(S22>4,5,IF((S22-TRUNC(S22))<0.3,TRUNC(S22),IF((S22-TRUNC(S22))>=0.7,TRUNC(S22)+0.7,TRUNC(S22)+0.3))) -> 1.3
A23: 15 | B23: CSE2022 | C23: 10422012 | D23: Le Van Vinh | E23: Bao | F23: 1 | G23: 10422012@student.vgu.edu.vn | H23: 2.7 | J23: =VLOOKUP(C23,Lab!$C$9:$I$126, 6, FALSE) -> 10 | K23: =VLOOKUP(C23,Lab!$C$9:$I$126, 7, FALSE) -> 10 | L23: =_xlfn.IFNA(VLOOKUP(C23, exam!$A$2:$C$115,3,FALSE),0) -> 7.5 | M23: 5 | R23: =J23*0.1+K23*0.1+MIN((L23+N23),10)*0.4+M23*0.4 -> 7 | S23: =IF(R23*10<50,5,ROUND(3*((100-R23*10)/50)+1,1)) -> 2.8 | T23: =IF(S23>4,5,IF((S23-TRUNC(S23))<0.3,TRUNC(S23),IF((S23-TRUNC(S23))>=0.7,TRUNC(S23)+0.7,TRUNC(S23)+0.3))) -> 2.7
A24: 16 | B24: CSE2022 | C24: 10422013 | D24: Huynh Trung | E24: Bao | F24: 1 | G24: 10422013@student.vgu.edu.vn | H24: 3.7 | J24: =VLOOKUP(C24,Lab!$C$9:$I$126, 6, FALSE) -> 10 | K24: =VLOOKUP(C24,Lab!$C$9:$I$126, 7, FALSE) -> 10 | L24: =_xlfn.IFNA(VLOOKUP(C24, exam!$A$2:$C$115,3,FALSE),0) -> 7.75 | R24: =J24*0.1+K24*0.1+MIN((L24+N24),10)*0.4+M24*0.4 -> 5.1 | S24: =IF(R24*10<50,5,ROUND(3*((100-R24*10)/50)+1,1)) -> 3.9 | T24: =IF(S24>4,5,IF((S24-TRUNC(S24))<0.3,TRUNC(S24),IF((S24-TRUNC(S24))>=0.7,TRUNC(S24)+0.7,TRUNC(S24)+0.3))) -> 3.7
A25: 17 | B25: CSE2022 | C25: 10422014 | D25: Nguyen Phuc | E25: Bao | F25: 1 | G25: 10422014@student.vgu.edu.vn | H25: 2.7 | J25: =VLOOKUP(C25,Lab!$C$9:$I$126, 6, FALSE) -> 0 | K25: =VLOOKUP(C25,Lab!$C$9:$I$126, 7, FALSE) -> 10 | L25: =_xlfn.IFNA(VLOOKUP(C25, exam!$A$2:$C$115,3,FALSE),0) -> 5.25 | M25: 10 | R25: =J25*0.1+K25*0.1+MIN((L25+N25),10)*0.4+M25*0.4 -> 7.1 | S25: =IF(R25*10<50,5,ROUND(3*((100-R25*10)/50)+1,1)) -> 2.7 | T25: =IF(S25>4,5,IF((S25-TRUNC(S25))<0.3,TRUNC(S25),IF((S25-TRUNC(S25))>=0.7,TRUNC(S25)+0.7,TRUNC(S25)+0.3))) -> 2.7
A26: 18 | B26: CSE2022 | C26: 10422015 | D26: Duong Vo Thien | E26: Bao | F26: 1 | G26: 10422015@student.vgu.edu.vn | H26: 2 | J26: =VLOOKUP(C26,Lab!$C$9:$I$126, 6, FALSE) -> 10 | K26: =VLOOKUP(C26,Lab!$C$9:$I$126, 7, FALSE) -> 10 | L26: =_xlfn.IFNA(VLOOKUP(C26, exam!$A$2:$C$115,3,FALSE),0) -> 7.25 | M26: 8 | R26: =J26*0.1+K26*0.1+MIN((L26+N26),10)*0.4+M26*0.4 -> 8.1 | S26: =IF(R26*10<50,5,ROUND(3*((100-R26*10)/50)+1,1)) -> 2.1 | T26: =IF(S26>4,5,IF((S26-TRUNC(S26))<0.3,TRUNC(S26),IF((S26-TRUNC(S26))>=0.7,TRUNC(S26)+0.7,TRUNC(S26)+0.3))) -> 2
A27: 19 | B27: CSE2022 | C27: 10422123 | D27: Huynh Thien | E27: Bao | F27: 1 | G27: 10422123@student.vgu.edu.vn | H27: 3.7 | J27: =VLOOKUP(C27,Lab!$C$9:$I$126, 6, FALSE) -> 0 | K27: =VLOOKUP(C27,Lab!$C$9:$I$126, 7, FALSE) -> 10 | L27: =_xlfn.IFNA(VLOOKUP(C27, exam!$A$2:$C$115,3,FALSE),0) -> 6.25 | M27: 5 | R27: =J27*0.1+K27*0.1+MIN((L27+N27),10)*0.4+M27*0.4 -> 5.5 | S27: =IF(R27*10<50,5,ROUND(3*((100-R27*10)/50)+1,1)) -> 3.7 | T27: =IF(S27>4,5,IF((S27-TRUNC(S27))<0.3,TRUNC(S27),IF((S27-TRUNC(S27))>=0.7,TRUNC(S27)+0.7,TRUNC(S27)+0.3))) -> 3.7
A28: 20 | B28: CSE2022 | C28: 10422089 | D28: Luong Tieu | E28: Cuong | F28: 1 | G28: 10422089@student.vgu.edu.vn | H28: 2.7 | J28: =VLOOKUP(C28,Lab!$C$9:$I$126, 6, FALSE) -> 0 | K28: =VLOOKUP(C28,Lab!$C$9:$I$126, 7, FALSE) -> 10 | L28: =_xlfn.IFNA(VLOOKUP(C28, exam!$A$2:$C$115,3,FALSE),0) -> 7 | M28: 8 | R28: =J28*0.1+K28*0.1+MIN((L28+N28),10)*0.4+M28*0.4 -> 7 | S28: =IF(R28*10<50,5,ROUND(3*((100-R28*10)/50)+1,1)) -> 2.8 | T28: =IF(S28>4,5,IF((S28-TRUNC(S28))<0.3,TRUNC(S28),IF((S28-TRUNC(S28))>=0.7,TRUNC(S28)+0.7,TRUNC(S28)+0.3))) -> 2.7
A29: 21 | B29: CSE2022 | C29: 10422017 | D29: Nguyen Tran Quoc | E29: Dat | F29: 1 | G29: 10422017@student.vgu.edu.vn | H29: 1 | J29: 10 | K29: =VLOOKUP(C29,Lab!$C$9:$I$126, 7, FALSE) -> 10 | L29: =_xlfn.IFNA(VLOOKUP(C29, exam!$A$2:$C$115,3,FALSE),0) -> 8.75 | M29: 10 | N29: 1 | R29: =J29*0.1+K29*0.1+MIN((L29+N29),10)*0.4+M29*0.4 -> 9.9 | S29: =IF(R29*10<50,5,ROUND(3*((100-R29*10)/50)+1,1)) -> 1.1 | T29: =IF(S29>4,5,IF((S29-TRUNC(S29))<0.3,TRUNC(S29),IF((S29-TRUNC(S29))>=0.7,TRUNC(S29)+0.7,TRUNC(S29)+0.3))) -> 1
A30: 22 | B30: CSE2022 | C30: 10422091 | D30: Le Thanh | E30: Dat | F30: 1 | G30: 10422091@student.vgu.edu.vn | H30: 1.7 | J30: =VLOOKUP(C30,Lab!$C$9:$I$126, 6, FALSE) -> 4 | K30: =VLOOKUP(C30,Lab!$C$9:$I$126, 7, FALSE) -> 10 | L30: =_xlfn.IFNA(VLOOKUP(C30, exam!$A$2:$C$115,3,FALSE),0) -> 8 | M30: 10 | R30: =J30*0.1+K30*0.1+MIN((L30+N30),10)*0.4+M30*0.4 -> 8.6 | S30: =IF(R30*10<50,5,ROUND(3*((100-R30*10)/50)+1,1)) -> 1.8 | T30: =IF(S30>4,5,IF((S30-TRUNC(S30))<0.3,TRUNC(S30),IF((S30-TRUNC(S30))>=0.7,TRUNC(S30)+0.7,TRUNC(S30)+0.3))) -> 1.7
A31: 23 | B31: CSE2022 | C31: 10422018 | D31: Cao Kim | E31: Do | F31: 1 | G31: 10422018@student.vgu.edu.vn | H31: 2 | J31: =VLOOKUP(C31,Lab!$C$9:$I$126, 6, FALSE) -> 0 | K31: =VLOOKUP(C31,Lab!$C$9:$I$126, 7, FALSE) -> 10 | L31: =_xlfn.IFNA(VLOOKUP(C31, exam!$A$2:$C$115,3,FALSE),0) -> 7.75 | M31: 10 | N31: 0 | R31: =J31*0.1+K31*0.1+MIN((L31+N31),10)*0.4+M31*0.4 -> 8.1 | S31: =IF(R31*10<50,5,ROUND(3*((100-R31*10)/50)+1,1)) -> 2.1 | T31: =IF(S31>4,5,IF((S31-TRUNC(S31))<0.3,TRUNC(S31),IF((S31-TRUNC(S31))>=0.7,TRUNC(S31)+0.7,TRUNC(S31)+0.3))) -> 2
A32: 24 | B32: CSE2022 | C32: 10422019 | D32: Tran Manh | E32: Duc | F32: 1 | G32: 10422019@student.vgu.edu.vn | H32: 1.7 | J32: =VLOOKUP(C32,Lab!$C$9:$I$126, 6, FALSE) -> 10 | K32: =VLOOKUP(C32,Lab!$C$9:$I$126, 7, FALSE) -> 10 | L32: =_xlfn.IFNA(VLOOKUP(C32, exam!$A$2:$C$115,3,FALSE),0) -> 6.25 | M32: 10 | N32: 1 | R32: =J32*0.1+K32*0.1+MIN((L32+N32),10)*0.4+M32*0.4 -> 8.9 | S32: =IF(R32*10<50,5,ROUND(3*((100-R32*10)/50)+1,1)) -> 1.7 | T32: =IF(S32>4,5,IF((S32-TRUNC(S32))<0.3,TRUNC(S32),IF((S32-TRUNC(S32))>=0.7,TRUNC(S32)+0.7,TRUNC(S32)+0.3))) -> 1.7
A33: 25 | B33: CSE2022 | C33: 10422092 | D33: Truong Huynh Anh | E33: Duc | F33: 1 | G33: 10422092@student.vgu.edu.vn | H33: 1.3 | J33: =VLOOKUP(C33,Lab!$C$9:$I$126, 6, FALSE) -> 10 | K33: =VLOOKUP(C33,Lab!$C$9:$I$126, 7, FALSE) -> 10 | L33: =_xlfn.IFNA(VLOOKUP(C33, exam!$A$2:$C$115,3,FALSE),0) -> 7.5 | M33: 10 | N33: 1 | R33: =J33*0.1+K33*0.1+MIN((L33+N33),10)*0.4+M33*0.4 -> 9.4 | S33: =IF(R33*10<50,5,ROUND(3*((100-R33*10)/50)+1,1)) -> 1.4 | T33: =IF(S33>4,5,IF((S33-TRUNC(S33))<0.3,TRUNC(S33),IF((S33-TRUNC(S33))>=0.7,TRUNC(S33)+0.7,TRUNC(S33)+0.3))) -> 1.3
A34: 26 | B34: CSE2022 | C34: 10422020 | D34: Pham Dao Quoc | E34: Dung | F34: 1 | G34: 10422020@student.vgu.edu.vn | H34: 3 | J34: =VLOOKUP(C34,Lab!$C$9:$I$126, 6, FALSE) -> 8 | K34: =VLOOKUP(C34,Lab!$C$9:$I$126, 7, FALSE) -> 10 | L34: =_xlfn.IFNA(VLOOKUP(C34, exam!$A$2:$C$115,3,FALSE),0) -> 6.75 | M34: 5 | R34: =J34*0.1+K34*0.1+MIN((L34+N34),10)*0.4+M34*0.4 -> 6.5 | S34: =IF(R34*10<50,5,ROUND(3*((100-R34*10)/50)+1,1)) -> 3.1 | T34: =IF(S34>4,5,IF((S34-TRUNC(S34))<0.3,TRUNC(S34),IF((S34-TRUNC(S34))>=0.7,TRUNC(S34)+0.7,TRUNC(S34)+0.3))) -> 3
A35: 27 | B35: CSE2022 | C35: 10422093 | D35: Pham Quang | E35: Dung | F35: 1 | G35: 10422093@student.vgu.edu.vn | H35: 2 | J35: =VLOOKUP(C35,Lab!$C$9:$I$126, 6, FALSE) -> 10 | K35: =VLOOKUP(C35,Lab!$C$9:$I$126, 7, FALSE) -> 10 | L35: =_xlfn.IFNA(VLOOKUP(C35, exam!$A$2:$C$115,3,FALSE),0) -> 5 | M35: 10 | N35: 1 | R35: =J35*0.1+K35*0.1+MIN((L35+N35),10)*0.4+M35*0.4 -> 8.4 | S35: =IF(R35*10<50,5,ROUND(3*((100-R35*10)/50)+1,1)) -> 2 | T35: =IF(S35>4,5,IF((S35-TRUNC(S35))<0.3,TRUNC(S35),IF((S35-TRUNC(S35))>=0.7,TRUNC(S35)+0.7,TRUNC(S35)+0.3))) -> 2
A36: 28 | B36: CSE2022 | C36: 10422021 | D36: Tran Hai | E36: Duong | F36: 1 | G36: 10422021@student.vgu.edu.vn | H36: 1 | J36: =VLOOKUP(C36,Lab!$C$9:$I$126, 6, FALSE) -> 10 | K36: =VLOOKUP(C36,Lab!$C$9:$I$126, 7, FALSE) -> 10 | L36: =_xlfn.IFNA(VLOOKUP(C36, exam!$A$2:$C$115,3,FALSE),0) -> 9.5 | M36: 10 | N36: 2 | R36: =J36*0.1+K36*0.1+MIN((L36+N36),10)*0.4+M36*0.4 -> 10 | S36: =IF(R36*10<50,5,ROUND(3*((100-R36*10)/50)+1,1)) -> 1 | T36: =IF(S36>4,5,IF((S36-TRUNC(S36))<0.3,TRUNC(S36),IF((S36-TRUNC(S36))>=0.7,TRUNC(S36)+0.7,TRUNC(S36)+0.3))) -> 1
A37: 29 | B37: CSE2022 | C37: 17417 | D37: Bui Le | E37: Duy | F37: 1 | G37: 17417@student.vgu.edu.vn | H37: 5 | J37: =VLOOKUP(C37,Lab!$C$9:$I$126, 6, FALSE) -> 0 | L37: =_xlfn.IFNA(VLOOKUP(C37, exam!$A$2:$C$115,3,FALSE),0) -> 3.75 | R37: =J37*0.1+K37*0.1+MIN((L37+N37),10)*0.4+M37*0.4 -> 1.5 | S37: =IF(R37*10<50,5,ROUND(3*((100-R37*10)/50)+1,1)) -> 5 | T37: =IF(S37>4,5,IF((S37-TRUNC(S37))<0.3,TRUNC(S37),IF((S37-TRUNC(S37))>=0.7,TRUNC(S37)+0.7,TRUNC(S37)+0.3))) -> 5
A38: 30 | B38: CSE2022 | C38: 10422022 | D38: Pham | E38: Duy | F38: 1 | G38: 10422022@student.vgu.edu.vn | H38: 1.3 | J38: =VLOOKUP(C38,Lab!$C$9:$I$126, 6, FALSE) -> 10 | K38: =VLOOKUP(C38,Lab!$C$9:$I$126, 7, FALSE) -> 10 | L38: =_xlfn.IFNA(VLOOKUP(C38, exam!$A$2:$C$115,3,FALSE),0) -> 7.75 | M38: 10 | N38: 1 | R38: =J38*0.1+K38*0.1+MIN((L38+N38),10)*0.4+M38*0.4 -> 9.5 | S38: =IF(R38*10<50,5,ROUND(3*((100-R38*10)/50)+1,1)) -> 1.3 | T38: =IF(S38>4,5,IF((S38-TRUNC(S38))<0.3,TRUNC(S38),IF((S38-TRUNC(S38))>=0.7,TRUNC(S38)+0.7,TRUNC(S38)+0.3))) -> 1.3
A39: 31 | B39: CSE2022 | C39: 10422023 | D39: Nguyen | E39: Duy | F39: 1 | G39: 10422023@student.vgu.edu.vn | H39: 1 | J39: =VLOOKUP(C39,Lab!$C$9:$I$126, 6, FALSE) -> 10 | K39: =VLOOKUP(C39,Lab!$C$9:$I$126, 7, FALSE) -> 10 | L39: =_xlfn.IFNA(VLOOKUP(C39, exam!$A$2:$C$115,3,FALSE),0) -> 8 | M39: 10 | N39: 1 | O39: bonus 2 not correct | R39: =J39*0.1+K39*0.1+MIN((L39+N39),10)*0.4+M39*0.4 -> 9.6 | S39: =IF(R39*10<50,5,ROUND(3*((100-R39*10)/50)+1,1)) -> 1.2 | T39: =IF(S39>4,5,IF((S39-TRUNC(S39))<0.3,TRUNC(S39),IF((S39-TRUNC(S39))>=0.7,TRUNC(S39)+0.7,TRUNC(S39)+0.3))) -> 1
A40: 32 | B40: CSE2022 | C40: 10422024 | D40: Nguyen Minh | E40: Giap | F40: 1 | G40: 10422024@student.vgu.edu.vn | H40: 1 | J40: =VLOOKUP(C40,Lab!$C$9:$I$126, 6, FALSE) -> 10 | K40: =VLOOKUP(C40,Lab!$C$9:$I$126, 7, FALSE) -> 10 | L40: =_xlfn.IFNA(VLOOKUP(C40, exam!$A$2:$C$115,3,FALSE),0) -> 8.5 | M40: 10 | N40: 1 | R40: =J40*0.1+K40*0.1+MIN((L40+N40),10)*0.4+M40*0.4 -> 9.8 | S40: =IF(R40*10<50,5,ROUND(3*((100-R40*10)/50)+1,1)) -> 1.1 | T40: =IF(S40>4,5,IF((S40-TRUNC(S40))<0.3,TRUNC(S40),IF((S40-TRUNC(S40))>=0.7,TRUNC(S40)+0.7,TRUNC(S40)+0.3))) -> 1
A41: 33 | B41: CSE2022 | C41: 10421015 | D41: Vo Thi Hong | E41: Ha | F41: 1 | G41: 10421015@student.vgu.edu.vn | H41: 2 | J41: =VLOOKUP(C41,Lab!$C$9:$I$126, 6, FALSE) -> 10 | K41: =VLOOKUP(C41,Lab!$C$9:$I$126, 7, FALSE) -> 10 | L41: =_xlfn.IFNA(VLOOKUP(C41, exam!$A$2:$C$115,3,FALSE),0) -> 5.75 | M41: 10 | N41: 0 | R41: =J41*0.1+K41*0.1+MIN((L41+N41),10)*0.4+M41*0.4 -> 8.3 | S41: =IF(R41*10<50,5,ROUND(3*((100-R41*10)/50)+1,1)) -> 2 | T41: =IF(S41>4,5,IF((S41-TRUNC(S41))<0.3,TRUNC(S41),IF((S41-TRUNC(S41))>=0.7,TRUNC(S41)+0.7,TRUNC(S41)+0.3))) -> 2
A42: 34 | B42: CSE2022 | C42: 10422025 | D42: Truong Thanh | E42: Hai | F42: 1 | G42: 10422025@student.vgu.edu.vn | H42: 1.3 | J42: =VLOOKUP(C42,Lab!$C$9:$I$126, 6, FALSE) -> 10 | K42: =VLOOKUP(C42,Lab!$C$9:$I$126, 7, FALSE) -> 10 | L42: =_xlfn.IFNA(VLOOKUP(C42, exam!$A$2:$C$115,3,FALSE),0) -> 7.75 | M42: 10 | N42: 1 | O42: Bonus 1 not corrrect, bonus 2 not check loss | R42: =J42*0.1+K42*0.1+MIN((L42+N42),10)*0.4+M42*0.4 -> 9.5 | S42: =IF(R42*10<50,5,ROUND(3*((100-R42*10)/50)+1,1)) -> 1.3 | T42: =IF(S42>4,5,IF((S42-TRUNC(S42))<0.3,TRUNC(S42),IF((S42-TRUNC(S42))>=0.7,TRUNC(S42)+0.7,TRUNC(S42)+0.3))) -> 1.3
A43: 35 | B43: CSE2022 | C43: 10422094 | D43: Do Nam | E43: Hai | F43: 1 | G43: 10422094@student.vgu.edu.vn | H43: 2 | J43: =VLOOKUP(C43,Lab!$C$9:$I$126, 6, FALSE) -> 8 | K43: =VLOOKUP(C43,Lab!$C$9:$I$126, 7, FALSE) -> 10 | L43: =_xlfn.IFNA(VLOOKUP(C43, exam!$A$2:$C$115,3,FALSE),0) -> 5.5 | M43: 10 | R43: =J43*0.1+K43*0.1+MIN((L43+N43),10)*0.4+M43*0.4 -> 8 | S43: =IF(R43*10<50,5,ROUND(3*((100-R43*10)/50)+1,1)) -> 2.2 | T43: =IF(S43>4,5,IF((S43-TRUNC(S43))<0.3,TRUNC(S43),IF((S43-TRUNC(S43))>=0.7,TRUNC(S43)+0.7,TRUNC(S43)+0.3))) -> 2
...

Sheet Lab
A1: Final Exam Result
D3: Module: Introduction to Data Science and AI | H3: Exam Date: 25.06.2024
D4: Lecturer: Dr. Nguyen Tuan Cuong | H4: Time: 09:30 - 11:00
D5: Semester: SS2024 | H5: Duration: 90 minutes
A8: No. | B8: Intake | C8: VGU ID | D8: Last Names and Middle Names | E8: Names | F8: Attempts | G8: Emails | H8: Lab1 | I8: Lab2 | J8: Note
A9: 1 | B9: CSE2021 | C9: 10421133 | D9: Bui Le | E9: Nhat | F9: 1 | G9: 10421133@student.vgu.edu.vn | H9: 10 | I9: 10
A10: 2 | B10: CSE2021 | C10: 10421127 | D10: Bui Van Hoang | E10: Vu | F10: 1 | G10: 10421127@student.vgu.edu.vn | H10: 10 | I10: 10 | J10: L1: numpy version inconsistent
A11: 3 | B11: CSE2022 | C11: 10422002 | D11: Pham Duc | E11: An | F11: 1 | G11: 10422002@student.vgu.edu.vn | H11: 0 | I11: 10 | J11: L1: copy full solution
A12: 4 | B12: CSE2022 | C12: 10422003 | D12: Le Thai | E12: An | F12: 1 | G12: 10422003@student.vgu.edu.vn | H12: 10 | I12: 10
A13: 5 | B13: CSE2022 | C13: 10422004 | D13: Yamashita Tri | E13: An | F13: 1 | G13: 10422004@student.vgu.edu.vn | H13: 10 | I13: 10
A14: 6 | B14: CSE2022 | C14: 10222040 | D14: Vu Duc Hung | E14: Anh | F14: 1 | G14: 10222040@student.vgu.edu.vn | H14: 0 | I14: 10 | J14: L1: copy full solution
A15: 7 | B15: CSE2022 | C15: 10422005 | D15: Nguyen Tran Tuan | E15: Anh | F15: 1 | G15: 10422005@student.vgu.edu.vn | H15: 0 | I15: 10 | J15: L1: copy full solution
A16: 8 | B16: CSE2022 | C16: 10422006 | D16: Nguyen Nhat | E16: Anh | F16: 1 | G16: 10422006@student.vgu.edu.vn | H16: 10 | I16: 10
A17: 9 | B17: CSE2022 | C17: 10422009 | D17: Nguyen Ngoc Minh | E17: Anh | F17: 1 | G17: 10422009@student.vgu.edu.vn | H17: 8 | I17: 10 | J17: L1: missing file 12
A18: 10 | B18: CSE2022 | C18: 10422086 | D18: Dang Dinh Tu | E18: Anh | F18: 1 | G18: 10422086@student.vgu.edu.vn | H18: 10 | I18: 10
A19: 11 | B19: CSE2022 | C19: 10422087 | D19: Ho Viet | E19: Bach | F19: 1 | G19: 10422087@student.vgu.edu.vn | H19: 10 | I19: 10
A20: 12 | B20: CSE2022 | C20: 10421069 | D20: Tran Gia | E20: Bao | F20: 1 | G20: 10421069@student.vgu.edu.vn | I20: 10
A21: 13 | B21: CSE2022 | C21: 10421125 | D21: Phan Le Quoc | E21: Bao | F21: 1 | G21: 10421125@student.vgu.edu.vn | I21: 10
A22: 14 | B22: CSE2022 | C22: 10422011 | D22: Huynh Thien | E22: Bao | F22: 1 | G22: 10422011@student.vgu.edu.vn | H22: 10 | I22: 10
A23: 15 | B23: CSE2022 | C23: 10422012 | D23: Le Van Vinh | E23: Bao | F23: 1 | G23: 10422012@student.vgu.edu.vn | H23: 10 | I23: 10 | J23: L1: có assert nhưng tên biến khác
A24: 16 | B24: CSE2022 | C24: 10422013 | D24: Huynh Trung | E24: Bao | F24: 1 | G24: 10422013@student.vgu.edu.vn | H24: 10 | I24: 10
A25: 17 | B25: CSE2022 | C25: 10422014 | D25: Nguyen Phuc | E25: Bao | F25: 1 | G25: 10422014@student.vgu.edu.vn | H25: 0 | I25: 10 | J25: L1: giống [1]
A26: 18 | B26: CSE2022 | C26: 10422015 | D26: Duong Vo Thien | E26: Bao | F26: 1 | G26: 10422015@student.vgu.edu.vn | H26: 10 | I26: 10
A27: 19 | B27: CSE2022 | C27: 10422123 | D27: Huynh Thien | E27: Bao | F27: 1 | G27: 10422123@student.vgu.edu.vn | H27: 0 | I27: 10 | J27: L1: copy sol (run count) + missing files.
A28: 20 | B28: CSE2022 | C28: 10422089 | D28: Luong Tieu | E28: Cuong | F28: 1 | G28: 10422089@student.vgu.edu.vn | I28: 10
A29: 21 | B29: CSE2022 | C29: 10422017 | D29: Nguyen Tran Quoc | E29: Dat | F29: 1 | G29: 10422017@student.vgu.edu.vn | I29: 10
A30: 22 | B30: CSE2022 | C30: 10422091 | D30: Le Thanh | E30: Dat | F30: 1 | G30: 10422091@student.vgu.edu.vn | H30: 4 | I30: 10 | J30: L1: copy full solution 10 12 13
A31: 23 | B31: CSE2022 | C31: 10422018 | D31: Cao Kim | E31: Do | F31: 1 | G31: 10422018@student.vgu.edu.vn | I31: 10
A32: 24 | B32: CSE2022 | C32: 10422019 | D32: Tran Manh | E32: Duc | F32: 1 | G32: 10422019@student.vgu.edu.vn | H32: 10 | I32: 10
A33: 25 | B33: CSE2022 | C33: 10422092 | D33: Truong Huynh Anh | E33: Duc | F33: 1 | G33: 10422092@student.vgu.edu.vn | H33: 10 | I33: 10
A34: 26 | B34: CSE2022 | C34: 10422020 | D34: Pham Dao Quoc | E34: Dung | F34: 1 | G34: 10422020@student.vgu.edu.vn | H34: 8 | I34: 10 | J34: L1: missing file 13
A35: 27 | B35: CSE2022 | C35: 10422093 | D35: Pham Quang | E35: Dung | F35: 1 | G35: 10422093@student.vgu.edu.vn | H35: 10 | I35: 10
A36: 28 | B36: CSE2022 | C36: 10422021 | D36: Tran Hai | E36: Duong | F36: 1 | G36: 10422021@student.vgu.edu.vn | H36: 10 | I36: 10
A37: 29 | B37: CSE2022 | C37: 17417 | D37: Bui Le | E37: Duy | F37: 1 | G37: 17417@student.vgu.edu.vn | I37: 10
A38: 30 | B38: CSE2022 | C38: 10422022 | D38: Pham | E38: Duy | F38: 1 | G38: 10422022@student.vgu.edu.vn | H38: 10 | I38: 10
A39: 31 | B39: CSE2022 | C39: 10422023 | D39: Nguyen | E39: Duy | F39: 1 | G39: 10422023@student.vgu.edu.vn | H39: 10 | I39: 10
A40: 32 | B40: CSE2022 | C40: 10422024 | D40: Nguyen Minh | E40: Giap | F40: 1 | G40: 10422024@student.vgu.edu.vn | H40: 10 | I40: 10
A41: 33 | B41: CSE2022 | C41: 10421015 | D41: Vo Thi Hong | E41: Ha | F41: 1 | G41: 10421015@student.vgu.edu.vn | H41: 10 | I41: 10
A42: 34 | B42: CSE2022 | C42: 10422025 | D42: Truong Thanh | E42: Hai | F42: 1 | G42: 10422025@student.vgu.edu.vn | H42: 10 | I42: 10
A43: 35 | B43: CSE2022 | C43: 10422094 | D43: Do Nam | E43: Hai | F43: 1 | G43: 10422094@student.vgu.edu.vn | H43: 8 | I43: 10 | J43: L1: 13 same as solution
...

Sheet exam
A1: ID | B1: File | C1: Score | D1: Num | E1: ID
A2: 10422002 | B2: imgs/dsai/9/018.jpg | C2: 7.25 | D2: 2 | E2: =10422000+D2 -> 10422002
A3: 10422003 | B3: imgs/dsai/10/012.jpg | C3: 5.5 | D3: 3 | E3: =10422000+D3 -> 10422003
A4: 10422004 | B4: imgs/dsai/10/020.jpg | C4: 9 | D4: 4 | E4: =10422000+D4 -> 10422004
A5: 10422005 | B5: imgs/dsai/9/008.jpg | C5: 8 | D5: 5 | E5: =10422000+D5 -> 10422005
A6: 10422006 | B6: imgs/dsai/10/008.jpg | C6: 4.75 | D6: 6 | E6: =10422000+D6 -> 10422006
A7: 10422009 | B7: imgs/dsai/10/006.jpg | C7: 5.5 | D7: 9 | E7: =10422000+D7 -> 10422009
A8: 10422011 | B8: imgs/dsai/9/004.jpg | C8: 6.5 | D8: 11 | E8: =10422000+D8 -> 10422011
A9: 10422012 | B9: imgs/dsai/9/014.jpg | C9: 7.5 | D9: 12 | E9: =10422000+D9 -> 10422012
A10: 10422013 | B10: imgs/dsai/9/002.jpg | C10: 7.75 | D10: 13 | E10: =10422000+D10 -> 10422013
A11: 10422014 | B11: imgs/dsai/9/012.jpg | C11: 5.25 | D11: 14 | E11: =10422000+D11 -> 10422014
A12: 10422015 | B12: imgs/dsai/10/014.jpg | C12: 7.25 | D12: 15 | E12: =10422000+D12 -> 10422015
A13: 10422017 | B13: imgs/dsai/10/018.jpg | C13: 8.75 | D13: 17 | E13: =10422000+D13 -> 10422017
... A101: 10422124 | B101: imgs/dsai/1/002.jpg | C101: 6.5 | D101: 124 | E101: =10422000+D101 -> 10422124
A102: 10421015 | B102: imgs/dsai/7/020.jpg | C102: 5.75 | D102: 1015 | E102: =10420000+D102 -> 10421015
A103: 10421026 | B103: imgs/dsai/5/018.jpg | C103: 7.25 | D103: 1026 | E103: =10420000+D103 -> 10421026
A104: 10421053 | B104: imgs/dsai/1/008.jpg | C104: 7.75 | D104: 1053 | E104: =10420000+D104 -> 10421053
A105: 10421067 | B105: imgs/dsai/1/014.jpg | C105: 5 | D105: 1067 | E105: =10420000+D105 -> 10421067
A106: 10421069 | B106: imgs/dsai/10/016.jpg | C106: 6.5 | D106: 1069 | E106: =10420000+D106 -> 10421069
A107: 10421098 | B107: imgs/dsai/3/014.jpg | C107: 7.75 | D107: 1098 | E107: =10420000+D107 -> 10421098
A108: 10421102 | B108: imgs/dsai/3/016.jpg | C108: 8.25 | D108: 1102 | E108: =10420000+D108 -> 10421102
A109: 10421124 | B109: imgs/dsai/2/018.jpg | C109: 4.5 | D109: 1124 | E109: =10420000+D109 -> 10421124
A110: 10421125 | B110: imgs/dsai/10/022.jpg | C110: 6.25 | D110: 1125 | E110: =10420000+D110 -> 10421125
A111: 10421127 | B111: imgs/dsai/9/020.jpg | C111: 7 | D111: 1127 | E111: =10420000+D111 -> 10421127
A112: 10421133 | B112: imgs/dsai/10/010.jpg | C112: 0.25 | D112: 1133 | E112: =10420000+D112 -> 10421133
A113: 17417 | B113: imgs/dsai/8/020.jpg | C113: 3.75 | D113: 17417 | E113: =D113 -> 17417
A114: 10222025 | B114: imgs/dsai/3/012.jpg | C114: 6 | D114: 10222025 | E114: =D114 -> 10222025
A115: 10222040 | B115: imgs/dsai/10/002.jpg | C115: 4.25 | D115: 10222040 | E115: =D115 -> 10222040
